Workbook

Sheet Summary
A1: Case Study: Student Attendance Management System – White Box Testing
A2: Basis path testing with control flow graphs on four core modules. Each module sheet holds its code, CFG, V(G), basis paths, test cases and coverage.
A4: 1. Modules under test and business rules (assumed)
A5: # | B5: Module | C5: Purpose | D5: Business rules
A6: 1 | B6: M1 Attendance Percentage | C6: Computes a student's attendance percentage for a subject. | D6: Percentage = (classes attended + approved medical-leave days) ÷ total classes × 100, capped at 100. Total classes must be > 0, otherwise INVALID.
A7: 2 | B7: M2 Exam Eligibility | C7: Decides whether a student may appear in the exam. | D7: 75% or more: ELIGIBLE. 65% to below 75%: CONDONED if condonation is approved, else DETAINED. Below 65%: DETAINED.
A8: 3 | B8: M3 Attendance Marking | C8: Totals one student's attendance from a list of daily status codes. | D8: P (present) = 1, L (late) = 0.5, any other code (A, absent) = 0.
A9: 4 | B9: M4 Attendance Alert | C9: Chooses the alert sent for a student at the end of the day. | D9: Checks in order: already alerted today, attendance ≥ 75%, 5+ consecutive absences, guardian contact on file.
A11: 2. Results (linked to the module sheets)
A12: # | B12: Module | C12: Function | D12: Nodes | E12: Edges | F12: Decisions | G12: V(G) | H12: Basis paths | I12: Infeasible | J12: Tests | K12: Passed | L12: Statement cov. | M12: Branch cov. | N12: Edge cov.
A13: 1 | B13: Attendance Percentage | C13: attendance_percentage(total, present, medical) | D13: =M1_AttendancePct!C49 -> 8 | E13: =M1_AttendancePct!C50 -> 10 | F13: =M1_AttendancePct!C51 -> 3 | G13: =M1_AttendancePct!C55 -> 4 | H13: =M1_AttendancePct!D65 -> 4 | I13: =M1_AttendancePct!D66 -> 0 | J13: =COUNTA(M1_AttendancePct!A70:A77) -> 8 | K13: =COUNTIF(M1_AttendancePct!G70:G77,"Pass") -> 8 | L13: =M1_AttendancePct!D103 -> 1 | M13: =M1_AttendancePct!D104 -> 1 | N13: =M1_AttendancePct!D105 -> 1
A14: 2 | B14: Exam Eligibility | C14: exam_eligibility(pct, condonation) | D14: =M2_Eligibility!C49 -> 8 | E14: =M2_Eligibility!C50 -> 10 | F14: =M2_Eligibility!C51 -> 3 | G14: =M2_Eligibility!C55 -> 4 | H14: =M2_Eligibility!D64 -> 4 | I14: =M2_Eligibility!D65 -> 0 | J14: =COUNTA(M2_Eligibility!A69:A77) -> 9 | K14: =COUNTIF(M2_Eligibility!G69:G77,"Pass") -> 9 | L14: =M2_Eligibility!D103 -> 1 | M14: =M2_Eligibility!D104 -> 1 | N14: =M2_Eligibility!D105 -> 1
A15: 3 | B15: Attendance Marking | C15: count_attendance(statuses) | D15: =M3_Marking!C50 -> 9 | E15: =M3_Marking!C51 -> 11 | F15: =M3_Marking!C52 -> 3 | G15: =M3_Marking!C56 -> 4 | H15: =M3_Marking!D69 -> 4 | I15: =M3_Marking!D70 -> 0 | J15: =COUNTA(M3_Marking!A74:A81) -> 8 | K15: =COUNTIF(M3_Marking!G74:G81,"Pass") -> 8 | L15: =M3_Marking!D109 -> 1 | M15: =M3_Marking!D110 -> 1 | N15: =M3_Marking!D111 -> 1
A16: 4 | B16: Attendance Alert | C16: attendance_alert(alerted_today, pct, absent_run, guardian) | D16: =M4_Alerts!C52 -> 10 | E16: =M4_Alerts!C53 -> 13 | F16: =M4_Alerts!C54 -> 4 | G16: =M4_Alerts!C58 -> 5 | H16: =M4_Alerts!D68 -> 5 | I16: =M4_Alerts!D69 -> 0 | J16: =COUNTA(M4_Alerts!A73:A81) -> 9 | K16: =COUNTIF(M4_Alerts!G73:G81,"Pass") -> 9 | L16: =M4_Alerts!D112 -> 1 | M16: =M4_Alerts!D113 -> 1 | N16: =M4_Alerts!D114 -> 1
B17: Total | G17: =SUM(G13:G16) -> 17 | H17: =SUM(H13:H16) -> 17 | I17: =SUM(I13:I16) -> 0 | J17: =SUM(J13:J16) -> 34 | K17: =SUM(K13:K16) -> 34
A19: 3. Key points
A20: • V(G) = E − N + 2 = decisions + 1. It is the minimum number of test cases needed to cover every independent path of a module.
A21: • Each module's basis set is built from a baseline path by flipping one decision at a time; supplementary and boundary tests are added on top.
A22: • Coverage = share of nodes (statement), T/F branches (decision) and edges that the suite's paths traverse. It recalculates if a test case is edited.
A23: • Actual outputs were obtained by running a Python implementation of each module, and each test's path was checked against its recorded node sequence. Yellow cells with blue text are editable inputs.

Sheet M1_AttendancePct
A1: Module 1: Attendance Percentage
A2: Module under test: attendance_percentage(total, present, medical) | Technique: basis path testing with control flow graph
A4: Rules (assumed): percentage = (classes attended + approved medical-leave days) ÷ total classes × 100, capped at 100. Total classes must be greater than 0.
A5: Returns the percentage rounded to 1 decimal place, or INVALID.
A6: Features tested: early return on invalid data, two independent if-assignments (join nodes), capping of over-counted attendance, final computed return.
A8: 1. Source code with CFG node mapping
A9: Line | B9: Source code | C9: Node
A10: 1 | B10: def attendance_percentage(total, present, medical): | C10: -
A11: 2 | B11: if total <= 0: | C11: N1
A12: 3 | B12: return 'INVALID' | C12: N2
A13: 4 | B13: if medical > 0: | C13: N3
A14: 5 | B14: present = present + medical | C14: N4
A15: 6 | B15: if present > total: | C15: N5
A16: 7 | B16: present = total | C16: N6
A17: 8 | B17: return round(present * 100 / total, 1) | C17: N7
A34: 2. Control flow graph – node table and edge table
A35: Node | B35: Statement | C35: Type | D35: Out-deg | E35: In-deg | G35: Edge | H35: From | I35: To | J35: Label | K35: Description
A36: 1 | B36: if total <= 0 | C36: Decision | D36: =COUNTIF($H$36:$H$45,A36) -> 2 | E36: =COUNTIF($I$36:$I$45,A36) -> 0 | G36: E1 | H36: 1 | I36: 2 | J36: T | K36: no classes held
A37: 2 | B37: return 'INVALID' | C37: Process | D37: =COUNTIF($H$36:$H$45,A37) -> 1 | E37: =COUNTIF($I$36:$I$45,A37) -> 1 | G37: E2 | H37: 1 | I37: 3 | J37: F | K37: valid total
A38: 3 | B38: if medical > 0 | C38: Decision | D38: =COUNTIF($H$36:$H$45,A38) -> 2 | E38: =COUNTIF($I$36:$I$45,A38) -> 1 | G38: E3 | H38: 3 | I38: 4 | J38: T | K38: medical leave approved
A39: 4 | B39: present = present + medical | C39: Process | D39: =COUNTIF($H$36:$H$45,A39) -> 1 | E39: =COUNTIF($I$36:$I$45,A39) -> 1 | G39: E4 | H39: 3 | I39: 5 | J39: F | K39: no medical leave
A40: 5 | B40: if present > total | C40: Decision | D40: =COUNTIF($H$36:$H$45,A40) -> 2 | E40: =COUNTIF($I$36:$I$45,A40) -> 2 | G40: E5 | H40: 4 | I40: 5 | J40: - | K40: leave added
A41: 6 | B41: present = total | C41: Process | D41: =COUNTIF($H$36:$H$45,A41) -> 1 | E41: =COUNTIF($I$36:$I$45,A41) -> 1 | G41: E6 | H41: 5 | I41: 6 | J41: T | K41: over-counted (cap)
A42: 7 | B42: return round(present*100/total, 1) | C42: Process | D42: =COUNTIF($H$36:$H$45,A42) -> 1 | E42: =COUNTIF($I$36:$I$45,A42) -> 2 | G42: E7 | H42: 5 | I42: 7 | J42: F | K42: within total
A43: 8 | B43: exit | C43: Exit | D43: =COUNTIF($H$36:$H$45,A43) -> 0 | E43: =COUNTIF($I$36:$I$45,A43) -> 2 | G43: E8 | H43: 6 | I43: 7 | J43: - | K43: capped
G44: E9 | H44: 2 | I44: 8 | J44: - | K44: exit
G45: E10 | H45: 7 | I45: 8 | J45: - | K45: exit
A47: 3. Cyclomatic complexity V(G)
A48: Parameter | B48: Formula / source | C48: Value
A49: Nodes (N) | B49: count of node table | C49: =COUNTA(A36:A43) -> 8
A50: Edges (E) | B50: count of edge table | C50: =COUNTA(G36:G45) -> 10
A51: Decision nodes (P) | B51: nodes of type Decision | C51: =COUNTIF(C36:C43,"Decision") -> 3
A52: V(G) – method 1 | B52: E − N + 2 | C52: =C50-C49+2 -> 4
A53: V(G) – method 2 | B53: P + 1 | C53: =C51+1 -> 4
A54: Methods agree? | B54: method 1 = method 2 | C54: =IF(C52=C53,"Yes","MISMATCH") -> Yes
A55: Cyclomatic complexity V(G) | B55: minimum number of tests required | C55: =C52 -> 4
A56: Rating | B56: 1-10 simple, 11-20 moderate, 21-50 complex, >50 unstable | C56: =IF(C55<=10,"Simple",IF(C55<=20,"Moderate",IF(C55<=50,"Complex","Unstable"))) -> Simple
A58: 4. Independent (basis) paths – baseline path, then flip one decision at a time
A59: Path | B59: Derivation | C59: Type | D59: Feasible? | E59: Node sequence | K59: Notes
A60: P1 | B60: Baseline: valid total, no medical leave, within total | C60: Basis | D60: Yes | E60: 1-3-5-7-8
...

Sheet M2_Eligibility
A1: Module 2: Exam Eligibility
A2: Module under test: exam_eligibility(pct, condonation) | Technique: basis path testing with control flow graph
A4: Rules (assumed): 75% or more is ELIGIBLE. From 65% up to 75% the student is CONDONED when condonation is approved, otherwise DETAINED. Below 65% is always DETAINED.
A5: Returns ELIGIBLE, CONDONED or DETAINED.
A6: Features tested: sequential decisions with early returns, boundary values at 75 and 65, two separate nodes returning DETAINED.
A8: 1. Source code with CFG node mapping
A9: Line | B9: Source code | C9: Node
A10: 1 | B10: def exam_eligibility(pct, condonation): | C10: -
A11: 2 | B11: if pct >= 75: | C11: N1
A12: 3 | B12: return 'ELIGIBLE' | C12: N2
A13: 4 | B13: if pct < 65: | C13: N3
A14: 5 | B14: return 'DETAINED' | C14: N4
A15: 6 | B15: if condonation: | C15: N5
A16: 7 | B16: return 'CONDONED' | C16: N6
A17: 8 | B17: return 'DETAINED' | C17: N7
A34: 2. Control flow graph – node table and edge table
A35: Node | B35: Statement | C35: Type | D35: Out-deg | E35: In-deg | G35: Edge | H35: From | I35: To | J35: Label | K35: Description
A36: 1 | B36: if pct >= 75 | C36: Decision | D36: =COUNTIF($H$36:$H$45,A36) -> 2 | E36: =COUNTIF($I$36:$I$45,A36) -> 0 | G36: E1 | H36: 1 | I36: 2 | J36: T | K36: meets 75%
A37: 2 | B37: return 'ELIGIBLE' | C37: Process | D37: =COUNTIF($H$36:$H$45,A37) -> 1 | E37: =COUNTIF($I$36:$I$45,A37) -> 1 | G37: E2 | H37: 1 | I37: 3 | J37: F | K37: below 75%
A38: 3 | B38: if pct < 65 | C38: Decision | D38: =COUNTIF($H$36:$H$45,A38) -> 2 | E38: =COUNTIF($I$36:$I$45,A38) -> 1 | G38: E3 | H38: 3 | I38: 4 | J38: T | K38: below 65%
A39: 4 | B39: return 'DETAINED' (below 65) | C39: Process | D39: =COUNTIF($H$36:$H$45,A39) -> 1 | E39: =COUNTIF($I$36:$I$45,A39) -> 1 | G39: E4 | H39: 3 | I39: 5 | J39: F | K39: 65% to below 75%
A40: 5 | B40: if condonation | C40: Decision | D40: =COUNTIF($H$36:$H$45,A40) -> 2 | E40: =COUNTIF($I$36:$I$45,A40) -> 1 | G40: E5 | H40: 5 | I40: 6 | J40: T | K40: condonation approved
A41: 6 | B41: return 'CONDONED' | C41: Process | D41: =COUNTIF($H$36:$H$45,A41) -> 1 | E41: =COUNTIF($I$36:$I$45,A41) -> 1 | G41: E6 | H41: 5 | I41: 7 | J41: F | K41: no condonation
A42: 7 | B42: return 'DETAINED' (not condoned) | C42: Process | D42: =COUNTIF($H$36:$H$45,A42) -> 1 | E42: =COUNTIF($I$36:$I$45,A42) -> 1 | G42: E7 | H42: 2 | I42: 8 | J42: - | K42: exit
A43: 8 | B43: exit | C43: Exit | D43: =COUNTIF($H$36:$H$45,A43) -> 0 | E43: =COUNTIF($I$36:$I$45,A43) -> 4 | G43: E8 | H43: 4 | I43: 8 | J43: - | K43: exit
G44: E9 | H44: 6 | I44: 8 | J44: - | K44: exit
G45: E10 | H45: 7 | I45: 8 | J45: - | K45: exit
A47: 3. Cyclomatic complexity V(G)
A48: Parameter | B48: Formula / source | C48: Value
A49: Nodes (N) | B49: count of node table | C49: =COUNTA(A36:A43) -> 8
A50: Edges (E) | B50: count of edge table | C50: =COUNTA(G36:G45) -> 10
A51: Decision nodes (P) | B51: nodes of type Decision | C51: =COUNTIF(C36:C43,"Decision") -> 3
A52: V(G) – method 1 | B52: E − N + 2 | C52: =C50-C49+2 -> 4
A53: V(G) – method 2 | B53: P + 1 | C53: =C51+1 -> 4
A54: Methods agree? | B54: method 1 = method 2 | C54: =IF(C52=C53,"Yes","MISMATCH") -> Yes
A55: Cyclomatic complexity V(G) | B55: minimum number of tests required | C55: =C52 -> 4
A56: Rating | B56: 1-10 simple, 11-20 moderate, 21-50 complex, >50 unstable | C56: =IF(C55<=10,"Simple",IF(C55<=20,"Moderate",IF(C55<=50,"Complex","Unstable"))) -> Simple
A58: 4. Independent (basis) paths – baseline path, then flip one decision at a time
A59: Path | B59: Derivation | C59: Type | D59: Feasible? | E59: Node sequence | K59: Notes
A60: P1 | B60: Baseline: 65-75%, no condonation | C60: Basis | D60: Yes | E60: 1-3-5-7-8
...

Sheet M3_Marking
A1: Module 3: Attendance Marking
A2: Module under test: count_attendance(statuses) | Technique: basis path testing with control flow graph
A4: Rules (assumed): each status code is P (present) = 1 credit, L (late) = 0.5 credit, anything else (A, absent) = 0.
A5: Returns the total credit as a number.
A6: Features tested: loop, if / elif chain inside the loop, join node (i += 1), empty-list path.
A8: 1. Source code with CFG node mapping
A9: Line | B9: Source code | C9: Node
A10: 1 | B10: def count_attendance(statuses): | C10: -
A11: 2 | B11: present = 0 | C11: N1
A12: 3 | B12: i = 0 | C12: N1
A13: 4 | B13: while i < len(statuses): | C13: N2
A14: 5 | B14: s = statuses[i] | C14: N3
A15: 6 | B15: if s == 'P': | C15: N3
A16: 7 | B16: present += 1 | C16: N4
A17: 8 | B17: elif s == 'L': | C17: N5
A18: 9 | B18: present += 0.5 | C18: N6
A19: 10 | B19: i += 1 | C19: N7
A20: 11 | B20: return present | C20: N8
A34: 2. Control flow graph – node table and edge table
A35: Node | B35: Statement | C35: Type | D35: Out-deg | E35: In-deg | G35: Edge | H35: From | I35: To | J35: Label | K35: Description
A36: 1 | B36: present = 0; i = 0 | C36: Start | D36: =COUNTIF($H$36:$H$46,A36) -> 1 | E36: =COUNTIF($I$36:$I$46,A36) -> 0 | G36: E1 | H36: 1 | I36: 2 | J36: - | K36: init → loop test
A37: 2 | B37: while i < len(statuses) | C37: Decision | D37: =COUNTIF($H$36:$H$46,A37) -> 2 | E37: =COUNTIF($I$36:$I$46,A37) -> 2 | G37: E2 | H37: 2 | I37: 3 | J37: T | K37: status left to read
A38: 3 | B38: s = statuses[i]; s == 'P' ? | C38: Decision | D38: =COUNTIF($H$36:$H$46,A38) -> 2 | E38: =COUNTIF($I$36:$I$46,A38) -> 1 | G38: E3 | H38: 2 | I38: 8 | J38: F | K38: all statuses read
A39: 4 | B39: present += 1 | C39: Process | D39: =COUNTIF($H$36:$H$46,A39) -> 1 | E39: =COUNTIF($I$36:$I$46,A39) -> 1 | G39: E4 | H39: 3 | I39: 4 | J39: T | K39: present
A40: 5 | B40: s == 'L' ? | C40: Decision | D40: =COUNTIF($H$36:$H$46,A40) -> 2 | E40: =COUNTIF($I$36:$I$46,A40) -> 1 | G40: E5 | H40: 3 | I40: 5 | J40: F | K40: not present
A41: 6 | B41: present += 0.5 | C41: Process | D41: =COUNTIF($H$36:$H$46,A41) -> 1 | E41: =COUNTIF($I$36:$I$46,A41) -> 1 | G41: E6 | H41: 4 | I41: 7 | J41: - | K41: to next status
A42: 7 | B42: i += 1 (join) | C42: Process | D42: =COUNTIF($H$36:$H$46,A42) -> 1 | E42: =COUNTIF($I$36:$I$46,A42) -> 3 | G42: E7 | H42: 5 | I42: 6 | J42: T | K42: late
A43: 8 | B43: return present | C43: Process | D43: =COUNTIF($H$36:$H$46,A43) -> 1 | E43: =COUNTIF($I$36:$I$46,A43) -> 1 | G43: E8 | H43: 5 | I43: 7 | J43: F | K43: absent
A44: 9 | B44: exit | C44: Exit | D44: =COUNTIF($H$36:$H$46,A44) -> 0 | E44: =COUNTIF($I$36:$I$46,A44) -> 1 | G44: E9 | H44: 6 | I44: 7 | J44: - | K44: to next status
G45: E10 | H45: 7 | I45: 2 | J45: - | K45: loop back-edge
G46: E11 | H46: 8 | I46: 9 | J46: - | K46: exit
A48: 3. Cyclomatic complexity V(G)
A49: Parameter | B49: Formula / source | C49: Value
A50: Nodes (N) | B50: count of node table | C50: =COUNTA(A36:A44) -> 9
A51: Edges (E) | B51: count of edge table | C51: =COUNTA(G36:G46) -> 11
A52: Decision nodes (P) | B52: nodes of type Decision | C52: =COUNTIF(C36:C44,"Decision") -> 3
A53: V(G) – method 1 | B53: E − N + 2 | C53: =C51-C50+2 -> 4
A54: V(G) – method 2 | B54: P + 1 | C54: =C52+1 -> 4
A55: Methods agree? | B55: method 1 = method 2 | C55: =IF(C53=C54,"Yes","MISMATCH") -> Yes
A56: Cyclomatic complexity V(G) | B56: minimum number of tests required | C56: =C53 -> 4
...

Sheet M4_Alerts
A1: Module 4: Attendance Alert
A2: Module under test: attendance_alert(alerted_today, pct, absent_run, guardian) | Technique: basis path testing with control flow graph
A4: Rules (assumed): checks run in strict order: already alerted today, attendance at least 75%, five or more consecutive absences, guardian contact on file.
A5: Returns SKIP_DUPLICATE, NO_ALERT, ESCALATE_TO_HOD, NOTIFY_STUDENT or NOTIFY_GUARDIAN (assumed alert names).
A6: Features tested: sequential decisions where an earlier check overrides later conditions, boundary values at 75% and 5 absences.
A8: 1. Source code with CFG node mapping
A9: Line | B9: Source code | C9: Node
A10: 1 | B10: def attendance_alert(alerted_today, pct, absent_run, guardian): | C10: -
A11: 2 | B11: if alerted_today: | C11: N1
A12: 3 | B12: return 'SKIP_DUPLICATE' | C12: N2
A13: 4 | B13: if pct >= 75: | C13: N3
A14: 5 | B14: return 'NO_ALERT' | C14: N4
A15: 6 | B15: if absent_run >= 5: | C15: N5
A16: 7 | B16: return 'ESCALATE_TO_HOD' | C16: N6
A17: 8 | B17: if not guardian: | C17: N7
A18: 9 | B18: return 'NOTIFY_STUDENT' | C18: N8
A19: 10 | B19: return 'NOTIFY_GUARDIAN' | C19: N9
A34: 2. Control flow graph – node table and edge table
A35: Node | B35: Statement | C35: Type | D35: Out-deg | E35: In-deg | G35: Edge | H35: From | I35: To | J35: Label | K35: Description
A36: 1 | B36: if alerted_today | C36: Decision | D36: =COUNTIF($H$36:$H$48,A36) -> 2 | E36: =COUNTIF($I$36:$I$48,A36) -> 0 | G36: E1 | H36: 1 | I36: 2 | J36: T | K36: already alerted today
A37: 2 | B37: return SKIP_DUPLICATE | C37: Process | D37: =COUNTIF($H$36:$H$48,A37) -> 1 | E37: =COUNTIF($I$36:$I$48,A37) -> 1 | G37: E2 | H37: 1 | I37: 3 | J37: F | K37: not yet alerted
A38: 3 | B38: if pct >= 75 | C38: Decision | D38: =COUNTIF($H$36:$H$48,A38) -> 2 | E38: =COUNTIF($I$36:$I$48,A38) -> 1 | G38: E3 | H38: 3 | I38: 4 | J38: T | K38: attendance ok
A39: 4 | B39: return NO_ALERT | C39: Process | D39: =COUNTIF($H$36:$H$48,A39) -> 1 | E39: =COUNTIF($I$36:$I$48,A39) -> 1 | G39: E4 | H39: 3 | I39: 5 | J39: F | K39: below 75%
A40: 5 | B40: if absent_run >= 5 | C40: Decision | D40: =COUNTIF($H$36:$H$48,A40) -> 2 | E40: =COUNTIF($I$36:$I$48,A40) -> 1 | G40: E5 | H40: 5 | I40: 6 | J40: T | K40: 5+ days absent
A41: 6 | B41: return ESCALATE_TO_HOD | C41: Process | D41: =COUNTIF($H$36:$H$48,A41) -> 1 | E41: =COUNTIF($I$36:$I$48,A41) -> 1 | G41: E6 | H41: 5 | I41: 7 | J41: F | K41: fewer than 5
A42: 7 | B42: if not guardian | C42: Decision | D42: =COUNTIF($H$36:$H$48,A42) -> 2 | E42: =COUNTIF($I$36:$I$48,A42) -> 1 | G42: E7 | H42: 7 | I42: 8 | J42: T | K42: no guardian contact
A43: 8 | B43: return NOTIFY_STUDENT | C43: Process | D43: =COUNTIF($H$36:$H$48,A43) -> 1 | E43: =COUNTIF($I$36:$I$48,A43) -> 1 | G43: E8 | H43: 7 | I43: 9 | J43: F | K43: guardian on file
A44: 9 | B44: return NOTIFY_GUARDIAN | C44: Process | D44: =COUNTIF($H$36:$H$48,A44) -> 1 | E44: =COUNTIF($I$36:$I$48,A44) -> 1 | G44: E9 | H44: 2 | I44: 10 | J44: - | K44: exit
A45: 10 | B45: exit | C45: Exit | D45: =COUNTIF($H$36:$H$48,A45) -> 0 | E45: =COUNTIF($I$36:$I$48,A45) -> 5 | G45: E10 | H45: 4 | I45: 10 | J45: - | K45: exit
G46: E11 | H46: 6 | I46: 10 | J46: - | K46: exit
G47: E12 | H47: 8 | I47: 10 | J47: - | K47: exit
G48: E13 | H48: 9 | I48: 10 | J48: - | K48: exit
A50: 3. Cyclomatic complexity V(G)
A51: Parameter | B51: Formula / source | C51: Value
A52: Nodes (N) | B52: count of node table | C52: =COUNTA(A36:A45) -> 10
A53: Edges (E) | B53: count of edge table | C53: =COUNTA(G36:G48) -> 13
A54: Decision nodes (P) | B54: nodes of type Decision | C54: =COUNTIF(C36:C45,"Decision") -> 4
A55: V(G) – method 1 | B55: E − N + 2 | C55: =C53-C52+2 -> 5
A56: V(G) – method 2 | B56: P + 1 | C56: =C54+1 -> 5
A57: Methods agree? | B57: method 1 = method 2 | C57: =IF(C55=C56,"Yes","MISMATCH") -> Yes
...
